<?xml version="1.0" ?>
<!-- =================================================================================== -->
<!-- |    This document was autogenerated by xacro from /opt/ros/kinetic/share/moveit_resources/panda_description/urdf/panda.urdf | -->
<!-- |    EDITING THIS FILE BY HAND IS NOT RECOMMENDED                                 | -->
<!-- =================================================================================== -->
<robot name="panda" xmlns:xacro="http://www.ros.org/wiki/xacro">
    <link name="world" />
    <link name="panda_link0">
        <visual>
            <geometry>
                <mesh filename="package://moveit_resources_panda_gazebo_description/meshes/visual/link0.dae" />
            </geometry>
        </visual>
        <collision>
            <geometry>
                <mesh filename="package://moveit_resources_panda_gazebo_description/meshes/collision/link0.stl" />
            </geometry>
        </collision>
        <inertial>
            <mass value="1.2" />
            <origin rpy="0 0 0" xyz="0 0 0.055" />
            <inertia ixx="0.00229" ixy="0" ixz="0" iyy="0.00216" iyz="0" izz="0.00229" />
        </inertial>
    </link>
    <joint name="world_to_panda_base" type="fixed">
        <parent link="world"/>
        <child link="panda_link0"/>
        <origin xyz="0 0.7 1.03" rpy="0 0 1.5708"/>
    </joint>
    <link name="panda_link1">
        <visual>
            <geometry>
                <mesh filename="package://moveit_resources_panda_gazebo_description/meshes/visual/link1.dae" />
            </geometry>
        </visual>
        <collision>
            <geometry>
                <mesh filename="package://moveit_resources_panda_gazebo_description/meshes/collision/link1.stl" />
            </geometry>
        </collision>
        <inertial>
            <mass value="2.0" />
            <origin rpy="0 0 0" xyz="0 0 0.130" />
            <inertia ixx="0.0136666666667" ixy="0" ixz="0" iyy="0.0118666666667" iyz="0" izz="0.003" />
        </inertial>
    </link>
    <joint name="panda_joint1" type="revolute">
        <safety_controller k_position="100.0" k_velocity="40.0" soft_lower_limit="-2.8973" soft_upper_limit="2.8973" />
        <origin rpy="0 0 0" xyz="0 0 0.333" />
        <parent link="panda_link0" />
        <child link="panda_link1" />
        <axis xyz="0 0 1" />
        <limit effort="87" lower="-2.9671" upper="2.9671" velocity="2.3925" />
        <dynamics D="1" K="7000" damping="0.003" friction="0.2" mu_coulomb="0" mu_viscous="16"/>
    </joint>
    <link name="panda_link2">
        <visual>
            <geometry>
                <mesh filename="package://moveit_resources_panda_gazebo_description/meshes/visual/link2.dae" />
            </geometry>
        </visual>
        <collision>
            <geometry>
                <mesh filename="package://moveit_resources_panda_gazebo_description/meshes/collision/link2.stl" />
            </geometry>
        </collision>
        <inertial>
            <mass value="2.0" />
            <origin rpy="0 0 0" xyz="0 -0.06 0.07" />
            <inertia ixx="0.0136666666667" ixy="0" ixz="0" iyy="0.0118666666667" iyz="0" izz="0.003" />
        </inertial>
    </link>
    <joint name="panda_joint2" type="revolute">
        <safety_controller k_position="100.0" k_velocity="40.0" soft_lower_limit="-1.7628" soft_upper_limit="1.7628" />
        <origin rpy="-1.57079632679 0 0" xyz="0 0 0" />
        <parent link="panda_link1" />
        <child link="panda_link2" />
        <axis xyz="0 0 1" />
        <limit effort="87" lower="-1.8326" upper="1.8326" velocity="2.3925" />
        <dynamics D="1" K="7000" damping="0.003" friction="0.2" mu_coulomb="0" mu_viscous="16"/>
    </joint>
    <link name="panda_link3">
        <visual>
            <geometry>
                <mesh filename="package://moveit_resources_panda_gazebo_description/meshes/visual/link3.dae" />
            </geometry>
        </visual>
        <collision>
            <geometry>
                <mesh filename="package://moveit_resources_panda_gazebo_description/meshes/collision/link3.stl" />
            </geometry>
        </collision>
        <inertial>
            <mass value="2.0" />
            <origin rpy="0 0 0" xyz="0 -0.06 0.130" />
            <inertia ixx="0.0136666666667" ixy="0" ixz="0" iyy="0.0118666666667" iyz="0" izz="0.003" />
        </inertial>
    </link>
    <joint name="panda_joint3" type="revolute">
        <safety_controller k_position="100.0" k_velocity="40.0" soft_lower_limit="-2.8973" soft_upper_limit="2.8973" />
        <origin rpy="1.57079632679 0 0" xyz="0 -0.316 0" />
        <parent link="panda_link2" />
        <child link="panda_link3" />
        <axis xyz="0 0 1" />
        <limit effort="87" lower="-2.9671" upper="2.9671" velocity="2.3925" />
        <dynamics D="1" K="7000" damping="0.003" friction="0.2" mu_coulomb="0" mu_viscous="16"/>
    </joint>
    <link name="panda_link4">
        <visual>
            <geometry>
                <mesh filename="package://moveit_resources_panda_gazebo_description/meshes/visual/link4.dae" />
            </geometry>
        </visual>
        <collision>
            <geometry>
                <mesh filename="package://moveit_resources_panda_gazebo_description/meshes/collision/link4.stl" />
            </geometry>
        </collision>
        <inertial>
            <mass value="2.0" />
            <origin rpy="0 0 0" xyz="0 0.06 0.07" />
            <inertia ixx="0.0136666666667" ixy="0" ixz="0" iyy="0.0118666666667" iyz="0" izz="0.003" />
        </inertial>
    </link>
    <joint name="panda_joint4" type="revolute">
        <safety_controller k_position="100.0" k_velocity="40.0" soft_lower_limit="-3.0718" soft_upper_limit="0.0175" />
        <origin rpy="1.57079632679 0 0" xyz="0.0825 0 0" />
        <parent link="panda_link3" />
        <child link="panda_link4" />
        <axis xyz="0 0 1" />
        <limit effort="87" lower="-3.1416" upper="0.0873" velocity="2.3925" />
        <dynamics D="1" K="7000" damping="0.003" friction="0.2" mu_coulomb="0" mu_viscous="16"/>
    </joint>
    <link name="panda_link5">
        <visual>
            <geometry>
                <mesh filename="package://moveit_resources_panda_gazebo_description/meshes/visual/link5.dae" />
            </geometry>
        </visual>
        <collision>
            <geometry>
                <mesh filename="package://moveit_resources_panda_gazebo_description/meshes/collision/link5.stl" />
            </geometry>
        </collision>
        <inertial>
            <mass value="2.0" />
            <origin rpy="0 0 0" xyz="0 0 0.124" />
            <inertia ixx="0.0126506666667" ixy="0" ixz="0" iyy="0.0108506666667" iyz="0" izz="0.003" />
        </inertial>
    </link>
    <joint name="panda_joint5" type="revolute">
        <safety_controller k_position="100.0" k_velocity="40.0" soft_lower_limit="-2.8973" soft_upper_limit="2.8973" />
        <origin rpy="-1.57079632679 0 0" xyz="-0.0825 0.384 0" />
        <parent link="panda_link4" />
        <child link="panda_link5" />
        <axis xyz="0 0 1" />
        <limit effort="12" lower="-2.9671" upper="2.9671" velocity="2.8710" />
        <dynamics D="1" K="7000" damping="0.003" friction="0.2" mu_coulomb="0" mu_viscous="16"/>
    </joint>
    <link name="panda_link6">
        <visual>
            <geometry>
                <mesh filename="package://moveit_resources_panda_gazebo_description/meshes/visual/link6.dae" />
            </geometry>
        </visual>
        <collision>
            <geometry>
                <mesh filename="package://moveit_resources_panda_gazebo_description/meshes/collision/link6.stl" />
            </geometry>
        </collision>
        <inertial>
            <mass value="1.0" />
            <origin rpy="0 0 0" xyz="0 0 0.0" />
            <inertia ixx="0.00260416666667" ixy="0" ixz="0" iyy="0.00260416666667" iyz="0" izz="0.00260416666667" />
        </inertial>
    </link>
    <joint name="panda_joint6" type="revolute">
        <safety_controller k_position="100.0" k_velocity="40.0" soft_lower_limit="-0.0175" soft_upper_limit="3.7525" />
        <origin rpy="1.57079632679 0 0" xyz="0 0 0" />
        <parent link="panda_link5" />
        <child link="panda_link6" />
        <axis xyz="0 0 1" />
        <limit effort="12" lower="-0.0873" upper="3.8223" velocity="2.8710" />
        <dynamics D="1" K="7000" damping="0.003" friction="0.2" mu_coulomb="0" mu_viscous="16"/>
    </joint>
    <link name="panda_link7">
        <visual>
            <geometry>
                <mesh filename="package://moveit_resources_panda_gazebo_description/meshes/visual/link7.dae" />
            </geometry>
        </visual>
        <collision>
            <geometry>
                <mesh filename="package://moveit_resources_panda_gazebo_description/meshes/collision/link7.stl" />
            </geometry>
        </collision>
        <inertial>
            <mass value="0.2" />
            <origin xyz="0 0 0" />
            <inertia ixx="6.66666666667e-05" ixy="0" ixz="0" iyy="6.66666666667e-05" iyz="0" izz="0.00012" />
        </inertial>
    </link>
    <joint name="panda_joint7" type="revolute">
        <safety_controller k_position="100.0" k_velocity="40.0" soft_lower_limit="-2.8973" soft_upper_limit="2.8973" />
        <origin rpy="1.57079632679 0 0" xyz="0.088 0 0" />
        <parent link="panda_link6" />
        <child link="panda_link7" />
        <axis xyz="0 0 1" />
        <limit effort="12" lower="-2.9671" upper="2.9671" velocity="2.8710" />
        <dynamics D="1" K="7000" damping="0.003" friction="0.2" mu_coulomb="0" mu_viscous="16"/>
    </joint>
    <link name="panda_link8" />
    <joint name="panda_joint8" type="fixed">
        <origin rpy="0 0 0" xyz="0 0 0.107" />
        <parent link="panda_link7" />
        <child link="panda_link8" />
        <axis xyz="0 0 0" />
    </joint>
    <joint name="panda_hand_joint" type="fixed">
        <parent link="panda_link8" />
        <child link="panda_hand" />
        <origin rpy="0 0 -0.785398163397" xyz="0 0 0" />
    </joint>
    <link name="panda_hand">
        <visual>
            <geometry>
                <mesh filename="package://moveit_resources_panda_gazebo_description/meshes/visual/hand.dae" />
            </geometry>
        </visual>
        <collision>
            <geometry>
                <mesh filename="package://moveit_resources_panda_gazebo_description/meshes/collision/hand.stl" />
            </geometry>
        </collision>
        <inertial>
            <origin rpy="0 0 0" xyz="-0.01 0 0.03"/>
            <mass value="0.73"/>
            <inertia ixx="0.001" ixy="0" ixz="0" iyy="0.0025" iyz="0" izz="0.0017"/>
        </inertial>
    </link>
    <link name="panda_leftfinger">
        <visual>
            <geometry>
                <mesh filename="package://moveit_resources_panda_gazebo_description/meshes/visual/finger.dae" />
            </geometry>
        </visual>
        <collision>
            <geometry>
                <mesh filename="package://moveit_resources_panda_gazebo_description/meshes/collision/finger.stl" />
            </geometry>
        </collision>
        <inertial>
            <origin rpy="0 0 0" xyz="0 0 0"/>
            <mass value="0.015"/>
            <inertia ixx="2.3749999999999997e-06" ixy="0" ixz="0" iyy="2.3749999999999997e-06" iyz="0" izz="7.5e-07"/>
        </inertial>
    </link>
    <link name="panda_rightfinger">
        <visual>
            <origin rpy="0 0 3.14159265359" xyz="0 0 0" />
            <geometry>
                <mesh filename="package://moveit_resources_panda_gazebo_description/meshes/visual/finger.dae" />
            </geometry>
        </visual>
        <collision>
            <origin rpy="0 0 3.14159265359" xyz="0 0 0" />
            <geometry>
                <mesh filename="package://moveit_resources_panda_gazebo_description/meshes/collision/finger.stl" />
            </geometry>
        </collision>
        <inertial>
            <origin rpy="0 0 0" xyz="0 0 0"/>
            <mass value="0.015"/>
            <inertia ixx="2.3749999999999997e-06" ixy="0" ixz="0" iyy="2.3749999999999997e-06" iyz="0" izz="7.5e-07"/>
        </inertial>
    </link>
    <joint name="panda_finger_joint1" type="prismatic">
        <parent link="panda_hand" />
        <child link="panda_leftfinger" />
        <origin rpy="0 0 0" xyz="0 0 0.0584" />
        <axis xyz="0 1 0" />
        <limit effort="20" lower="0.0" upper="0.04" velocity="0.2" />
        <dynamics damping="0.3"/>
    </joint>
    <joint name="panda_finger_joint2" type="prismatic">
        <parent link="panda_hand" />
        <child link="panda_rightfinger" />
        <origin rpy="0 0 0" xyz="0 0 0.0584" />
        <axis xyz="0 -1 0" />
        <limit effort="20" lower="0.0" upper="0.04" velocity="0.2" />
        <mimic joint="panda_finger_joint1" />
        <dynamics damping="0.3"/>
    </joint>
    <gazebo reference="panda_joint1">
        <!-- Needed for ODE to output external wrenches on joints -->
        <provideFeedback>true</provideFeedback>
    </gazebo>
    <transmission name="panda_joint1_transmission">
        <type>transmission_interface/SimpleTransmission</type>
        <joint name="panda_joint1">
            <hardwareInterface>hardware_interface/PositionJointInterface</hardwareInterface>
        </joint>
        <actuator name="panda_joint1_motor">
            <hardwareInterface>hardware_interface/PositionJointInterface</hardwareInterface>
        </actuator>
    </transmission>
    <gazebo reference="panda_joint2">
        <!-- Needed for ODE to output external wrenches on joints -->
        <provideFeedback>true</provideFeedback>
    </gazebo>
    <transmission name="panda_joint2_transmission">
        <type>transmission_interface/SimpleTransmission</type>
        <joint name="panda_joint2">
            <hardwareInterface>hardware_interface/PositionJointInterface</hardwareInterface>
        </joint>
        <actuator name="panda_joint2_motor">
            <hardwareInterface>hardware_interface/PositionJointInterface</hardwareInterface>
        </actuator>
    </transmission>
    <gazebo reference="panda_joint3">
        <!-- Needed for ODE to output external wrenches on joints -->
        <provideFeedback>true</provideFeedback>
    </gazebo>
    <transmission name="panda_joint3_transmission">
        <type>transmission_interface/SimpleTransmission</type>
        <joint name="panda_joint3">
            <hardwareInterface>hardware_interface/PositionJointInterface</hardwareInterface>
        </joint>
        <actuator name="panda_joint3_motor">
            <hardwareInterface>hardware_interface/PositionJointInterface</hardwareInterface>
        </actuator>
    </transmission>
    <gazebo reference="panda_joint4">
        <!-- Needed for ODE to output external wrenches on joints -->
        <provideFeedback>true</provideFeedback>
    </gazebo>
    <transmission name="panda_joint4_transmission">
        <type>transmission_interface/SimpleTransmission</type>
        <joint name="panda_joint4">
            <hardwareInterface>hardware_interface/PositionJointInterface</hardwareInterface>
        </joint>
        <actuator name="panda_joint4_motor">
            <hardwareInterface>hardware_interface/PositionJointInterface</hardwareInterface>
        </actuator>
    </transmission>
    <gazebo reference="panda_joint5">
        <!-- Needed for ODE to output external wrenches on joints -->
        <provideFeedback>true</provideFeedback>
    </gazebo>
    <transmission name="panda_joint5_transmission">
        <type>transmission_interface/SimpleTransmission</type>
        <joint name="panda_joint5">
            <hardwareInterface>hardware_interface/PositionJointInterface</hardwareInterface>
        </joint>
        <actuator name="panda_joint5_motor">
            <hardwareInterface>hardware_interface/PositionJointInterface</hardwareInterface>
        </actuator>
    </transmission>
    <gazebo reference="panda_joint6">
        <!-- Needed for ODE to output external wrenches on joints -->
        <provideFeedback>true</provideFeedback>
    </gazebo>
    <transmission name="panda_joint6_transmission">
        <type>transmission_interface/SimpleTransmission</type>
        <joint name="panda_joint6">
            <hardwareInterface>hardware_interface/PositionJointInterface</hardwareInterface>
        </joint>
        <actuator name="panda_joint6_motor">
            <hardwareInterface>hardware_interface/PositionJointInterface</hardwareInterface>
        </actuator>
    </transmission>
    <gazebo reference="panda_joint7">
        <!-- Needed for ODE to output external wrenches on joints -->
        <provideFeedback>true</provideFeedback>
    </gazebo>
    <transmission name="panda_joint7_transmission">
        <type>transmission_interface/SimpleTransmission</type>
        <joint name="panda_joint7">
            <hardwareInterface>hardware_interface/PositionJointInterface</hardwareInterface>
        </joint>
        <actuator name="panda_joint7_motor">
            <hardwareInterface>hardware_interface/PositionJointInterface</hardwareInterface>
        </actuator>
    </transmission>
    <gazebo reference="panda_finger_joint1">
        <!-- Needed for ODE to output external wrenches on joints -->
        <provideFeedback>true</provideFeedback>
    </gazebo>
    <transmission name="panda_finger_joint1_transmission">
        <type>transmission_interface/SimpleTransmission</type>
        <joint name="panda_finger_joint1">
            <!--hardwareInterface>hardware_interface/EffortJointInterface</hardwareInterface-->
            <hardwareInterface>hardware_interface/PositionJointInterface</hardwareInterface>
        </joint>
        <actuator name="panda_finger_joint1_motor">
            <!--hardwareInterface>hardware_interface/EffortJointInterface</hardwareInterface-->
            <hardwareInterface>hardware_interface/PositionJointInterface</hardwareInterface>
        </actuator>
    </transmission>
    <gazebo reference="panda_finger_joint2">
        <!-- Needed for ODE to output external wrenches on joints -->
        <provideFeedback>true</provideFeedback>
    </gazebo>
    <transmission name="panda_finger_joint2_transmission">
        <type>transmission_interface/SimpleTransmission</type>
        <joint name="panda_finger_joint2">
            <!--hardwareInterface>hardware_interface/EffortJointInterface</hardwareInterface-->
            <hardwareInterface>hardware_interface/PositionJointInterface</hardwareInterface>
        </joint>
        <actuator name="panda_finger_joint2_motor">
            <!--hardwareInterface>hardware_interface/EffortJointInterface</hardwareInterface-->
            <hardwareInterface>hardware_interface/PositionJointInterface</hardwareInterface>
        </actuator>
    </transmission>
    <gazebo reference="panda_leftfinger">
        <collision>
            <max_contacts>10</max_contacts>
            <surface>
                <contact>
                    <ode>
                    <!-- These two parameter need application specific tuning. -->
                    <!-- Usually you want no "snap out" velocity and a generous -->
                    <!-- penetration depth to keep the grasping stable -->
                    <max_vel>0</max_vel>
                    <min_depth>0.001</min_depth>
                    </ode>
                </contact>
                <friction>
                    <ode>
                        <mu>1.13</mu>
                        <mu2>1.13</mu2>
                    </ode>
                </friction>
                <bounce/>
            </surface>
        </collision>
    </gazebo>
    <gazebo reference="panda_rightfinger">
        <collision>
            <max_contacts>10</max_contacts>
            <surface>
                <contact>
                    <ode>
                    <!-- These two parameter need application specific tuning. -->
                    <!-- Usually you want no "snap out" velocity and a generous -->
                    <!-- penetration depth to keep the grasping stable -->
                    <max_vel>0</max_vel>
                    <min_depth>0.001</min_depth>
                    </ode>
                </contact>
                <friction>
                    <ode>
                        <mu>1.13</mu>
                        <mu2>1.13</mu2>
                    </ode>
                </friction>
                <bounce/>
            </surface>
        </collision>
    </gazebo>
</robot>
